$ python -m utils.pdf_to_xml_windows
Input PDF directory: resources\pdf
Output XML directory: resources\out_xml
GROBID server does not appear up and running, the connection to the server failed
Traceback (most recent call last):
  File "C:\Users\aphase\AppData\Local\Programs\Python\Python313\Lib\site-packages\urllib3\connectionpool.py", line 464, in _make_request
    self._validate_conn(conn)
    ~~~~~~~~~~~~~~~~~~~^^^^^^
  File "C:\Users\aphase\AppData\Local\Programs\Python\Python313\Lib\site-packages\urllib3\connectionpool.py", line 1093, in _validate_conn
    conn.connect()
    ~~~~~~~~~~~~^^
  File "C:\Users\aphase\AppData\Local\Programs\Python\Python313\Lib\site-packages\urllib3\connection.py", line 790, in connect
    sock_and_verified = _ssl_wrap_socket_and_match_hostname(
        sock=sock,
    ...<14 lines>...
        assert_fingerprint=self.assert_fingerprint,
    )
  File "C:\Users\aphase\AppData\Local\Programs\Python\Python313\Lib\site-packages\urllib3\connection.py", line 969, in _ssl_wrap_socket_and_match_hostname
    ssl_sock = ssl_wrap_socket(
        sock=sock,
    ...<8 lines>...
        tls_in_tls=tls_in_tls,
    )
  File "C:\Users\aphase\AppData\Local\Programs\Python\Python313\Lib\site-packages\urllib3\util\ssl_.py", line 480, in ssl_wrap_socket
    ssl_sock = _ssl_wrap_socket_impl(sock, context, tls_in_tls, server_hostname)
  File "C:\Users\aphase\AppData\Local\Programs\Python\Python313\Lib\site-packages\urllib3\util\ssl_.py", line 524, in _ssl_wrap_socket_impl
    return ssl_context.wrap_socket(sock, server_hostname=server_hostname)
           ~~~~~~~~~~~~~~~~~~~~~~~^^^^^^^^^^^^^^^^^^^^^^^^^^^^^^^^^^^^^^^
  File "C:\Users\aphase\AppData\Local\Programs\Python\Python313\Lib\ssl.py", line 455, in wrap_socket
    return self.sslsocket_class._create(
           ~~~~~~~~~~~~~~~~~~~~~~~~~~~~^
        sock=sock,
        ^^^^^^^^^^
    ...<5 lines>...
        session=session
        ^^^^^^^^^^^^^^^
    )
    ^
  File "C:\Users\aphase\AppData\Local\Programs\Python\Python313\Lib\ssl.py", line 1076, in _create
    self.do_handshake()
    ~~~~~~~~~~~~~~~~~^^
  File "C:\Users\aphase\AppData\Local\Programs\Python\Python313\Lib\ssl.py", line 1372, in do_handshake
    self._sslobj.do_handshake()
    ~~~~~~~~~~~~~~~~~~~~~~~~~^^
ssl.SSLError: [SSL: WRONG_VERSION_NUMBER] wrong version number (_ssl.c:1028)

During handling of the above exception, another exception occurred:

Traceback (most recent call last):
  File "C:\Users\aphase\AppData\Local\Programs\Python\Python313\Lib\site-packages\urllib3\connectionpool.py", line 787, in urlopen
    response = self._make_request(
        conn,
    ...<10 lines>...
        **response_kw,
    )
  File "C:\Users\aphase\AppData\Local\Programs\Python\Python313\Lib\site-packages\urllib3\connectionpool.py", line 488, in _make_request
    raise new_e
urllib3.exceptions.SSLError: [SSL: WRONG_VERSION_NUMBER] wrong version number (_ssl.c:1028)

aphase@LAPTOP-3U6K5V9L MINGW64 ~/solid-state-battery-test/solid-state-battery-LLM (main)
$ python -m utils.pdf_to_xml_windows
Input PDF directory: resources\pdf
Output XML directory: resources\out_xml
GROBID server is up and running
Processing of resources\pdf\1-s2.0-S2352152X24035497-main.pdf failed with error 408 , None
Processing of resources\pdf\d4ya00138a.pdf failed with error 408 , None
Processing of resources\pdf\1-s2.0-S1452398123157324-main.pdf failed with error 408 , None
Processing of resources\pdf\d4ra06867j.pdf failed with error 408 , None
Processing of resources\pdf\1-s2.0-S2950264025000371-main.pdf failed with error 408 , None
Processing of resources\pdf\1-s2.0-S1385894725024593-main.pdf failed with error 408 , None
Processing of resources\pdf\1-s2.0-S1631074804003418-main.pdf failed with error 408 , None
Processing of resources\pdf\1-s2.0-S1631074804003406-main.pdf failed with error 408 , None
Processing of resources\pdf\d4sc06492e.pdf failed with error 408 , None
Processing of resources\pdf\1-s2.0-S2949736124000873-main.pdf failed with error 408 , None

PDF to XML conversion complete.

python -m utils.xml_to_json \
    --input-xml ./resources/out_xml \
    --input-xml-openalex ./resources/out_xml \
    --output-json ./resources/out_json
$ python -m utils.xml_to_json     --input-xml ./resources/out_xml     --input-xml-openalex ./resources/out_xml     --output-json ./resources/out_json
Found 10 XML files to process...
--------------------------------------------------

==============================
      Processing Summary
==============================
Total XML files found: 10
Successfully converted:  1
Rejected (license):    9
Failed (errors):       0
==============================


aphase@LAPTOP-3U6K5V9L MINGW64 ~/solid-state-battery-test/solid-state-battery-LLM (dev)
$ ./run_task_d.bash
[STEP 1] Running paper_scraping.py for years 2026 to 2027
Traceback (most recent call last):
  File "C:\Users\aphase\solid-state-battery-test\solid-state-battery-LLM\paper_scraping.py", line 2, in <module>
    from dotenv import load_dotenv
ModuleNotFoundError: No module named 'dotenv'
[STEP 2] Converting PDFs to XML using Grobid
Python was not found; run without arguments to install from the Microsoft Store, or disable this shortcut from Settings > Apps > Advanced app settings > App execution aliases.
Python was not found; run without arguments to install from the Microsoft Store, or disable this shortcut from Settings > Apps > Advanced app settings > App execution aliases.
[STEP 3] Searching XML files for query: battery
Traceback (most recent call last):
  File "C:\Users\aphase\solid-state-battery-test\solid-state-battery-LLM\search_query.py", line 3, in <module>
    from utils.utils import search_xml_content
  File "C:\Users\aphase\solid-state-battery-test\solid-state-battery-LLM\utils\utils.py", line 12, in <module>
    import pandas as pd
ModuleNotFoundError: No module named 'pandas'
[STEP 4] Converting XMLs to JSON
Python was not found; run without arguments to install from the Microsoft Store, or disable this shortcut from Settings > Apps > Advanced app settings > App execution aliases.
[STEP 5] Correcting extracted text of JSON
garbledlist.json
Traceback (most recent call last):
  File "C:\Users\aphase\solid-state-battery-test\solid-state-battery-LLM\json_correction.py", line 34, in <module>
    main(args)
    ~~~~^^^^^^
  File "C:\Users\aphase\solid-state-battery-test\solid-state-battery-LLM\json_correction.py", line 18, in main
    fj.fix_json(target_filepath, output_filepath)
    ~~~~~~~~~~~^^^^^^^^^^^^^^^^^^^^^^^^^^^^^^^^^^
  File "C:\Users\aphase\solid-state-battery-test\solid-state-battery-LLM\utils\fix_json_utils.py", line 351, in fix_json
    fixed_paper_json["title"] = fix_text_in_a_lump(title)
                                ~~~~~~~~~~~~~~~~~~^^^^^^^
  File "C:\Users\aphase\solid-state-battery-test\solid-state-battery-LLM\utils\fix_json_utils.py", line 321, in fix_text_in_a_lump
    fixed_text = replace_garbled(text)
  File "C:\Users\aphase\solid-state-battery-test\solid-state-battery-LLM\utils\fix_json_utils.py", line 297, in replace_garbled
    wordlist: dict = json.load(f)
                     ~~~~~~~~~^^^
  File "C:\Users\aphase\AppData\Local\Programs\Python\Python313\Lib\json\__init__.py", line 293, in load
    return loads(fp.read(),
                 ~~~~~~~^^
UnicodeDecodeError: 'cp932' codec can't decode byte 0x8e in position 136: illegal multibyte sequence


