$ python -m utils.pdf_to_xml_windows
Input PDF directory: resources\pdf
Output XML directory: resources\out_xml
GROBID server does not appear up and running, the connection to the server failed
Traceback (most recent call last):
  File "C:\Users\aphase\AppData\Local\Programs\Python\Python313\Lib\site-packages\urllib3\connectionpool.py", line 464, in _make_request
    self._validate_conn(conn)
    ~~~~~~~~~~~~~~~~~~~^^^^^^
  File "C:\Users\aphase\AppData\Local\Programs\Python\Python313\Lib\site-packages\urllib3\connectionpool.py", line 1093, in _validate_conn
    conn.connect()
    ~~~~~~~~~~~~^^
  File "C:\Users\aphase\AppData\Local\Programs\Python\Python313\Lib\site-packages\urllib3\connection.py", line 790, in connect
    sock_and_verified = _ssl_wrap_socket_and_match_hostname(
        sock=sock,
    ...<14 lines>...
        assert_fingerprint=self.assert_fingerprint,
    )
  File "C:\Users\aphase\AppData\Local\Programs\Python\Python313\Lib\site-packages\urllib3\connection.py", line 969, in _ssl_wrap_socket_and_match_hostname
    ssl_sock = ssl_wrap_socket(
        sock=sock,
    ...<8 lines>...
        tls_in_tls=tls_in_tls,
    )
  File "C:\Users\aphase\AppData\Local\Programs\Python\Python313\Lib\site-packages\urllib3\util\ssl_.py", line 480, in ssl_wrap_socket
    ssl_sock = _ssl_wrap_socket_impl(sock, context, tls_in_tls, server_hostname)
  File "C:\Users\aphase\AppData\Local\Programs\Python\Python313\Lib\site-packages\urllib3\util\ssl_.py", line 524, in _ssl_wrap_socket_impl
    return ssl_context.wrap_socket(sock, server_hostname=server_hostname)
           ~~~~~~~~~~~~~~~~~~~~~~~^^^^^^^^^^^^^^^^^^^^^^^^^^^^^^^^^^^^^^^
  File "C:\Users\aphase\AppData\Local\Programs\Python\Python313\Lib\ssl.py", line 455, in wrap_socket
    return self.sslsocket_class._create(
           ~~~~~~~~~~~~~~~~~~~~~~~~~~~~^
        sock=sock,
        ^^^^^^^^^^
    ...<5 lines>...
        session=session
        ^^^^^^^^^^^^^^^
    )
    ^
  File "C:\Users\aphase\AppData\Local\Programs\Python\Python313\Lib\ssl.py", line 1076, in _create
    self.do_handshake()
    ~~~~~~~~~~~~~~~~~^^
  File "C:\Users\aphase\AppData\Local\Programs\Python\Python313\Lib\ssl.py", line 1372, in do_handshake
    self._sslobj.do_handshake()
    ~~~~~~~~~~~~~~~~~~~~~~~~~^^
ssl.SSLError: [SSL: WRONG_VERSION_NUMBER] wrong version number (_ssl.c:1028)

During handling of the above exception, another exception occurred:

Traceback (most recent call last):
  File "C:\Users\aphase\AppData\Local\Programs\Python\Python313\Lib\site-packages\urllib3\connectionpool.py", line 787, in urlopen
    response = self._make_request(
        conn,
    ...<10 lines>...
        **response_kw,
    )
  File "C:\Users\aphase\AppData\Local\Programs\Python\Python313\Lib\site-packages\urllib3\connectionpool.py", line 488, in _make_request
    raise new_e
urllib3.exceptions.SSLError: [SSL: WRONG_VERSION_NUMBER] wrong version number (_ssl.c:1028)

